##### 예외
- 예외 발생을 선언하지 않음
- 예외를 캐치하도록 강제하지 않음
- Exception, Error 타입을 제공하나, 어떤 타입으로도 throw 할 수 있음 (그러나 Exception, Error를 일반적으로 사용)

```
throw FormatException('Expected at least 1 section');
throw 'Out of llamas!';
```

##### catch
```
try {
  breedMoreLlamas();
} on OutOfLlamasException {
  // 특정한 예외
  buyMoreLlamas();
} on Exception catch (e) {
  // Exception 타입인 예외
  print('Unknown exception: $e');
} catch (e) {
  // 타입을 정하지 않은 catch 절로 모든 예외를 처리
  print('Something really unknown: $e');
}
```

- catch(e, s) 에서 e는 e 에러, s 는 StackTrace 임
```
testFunc() => throw Exception("test error");

void main() {
   try {
      testFunc();
   }catch (e, s) {
      print('error:\n $e');
      print('Stack trace:\n $s');
   }
}

error:
 Exception: test error
Stack trace:
 #0      testFunc (file:///$path/DartTest.dart:6:15)
#1      main (file:///$path/DartTest.dart:10:7)
#2      _delayEntrypointInvocation.<anonymous closure> (dart:isolate-patch/isolate_patch.dart:315:19)
#3      _RawReceivePort._handleMessage (dart:isolate-patch/isolate_patch.dart:194:12)
```

- rethrow를 사용하여 다시 throw 가능
```
void misbehave() {
   try {
      dynamic foo = true;
      print(foo++); // 런타임 에러
   } catch (e) {
      print('misbehave() $e');
      rethrow; // 호출자가 예외를 확인 할 수 있도록 허락, throw e 와 같음 
   }
}

void main() {
   try {
      misbehave();
   } catch (e) {
      print('main() $e');
   }
}
```

##### finally 
```
try {
  breedMoreLlamas();
} finally {
  // 예외가 발생되더라도, 항상 실행됩니다.
  cleanLlamaStalls();
}
```
